[2023-10-09T21:11:38.659+0000] {taskinstance.py:1159} INFO - Dependencies all met for dep_context=non-requeueable deps ti=<TaskInstance: raddit_data_pipeline.popularity_data_injection manual__2023-10-09T21:11:04.419599+00:00 [queued]>
[2023-10-09T21:11:38.679+0000] {taskinstance.py:1159} INFO - Dependencies all met for dep_context=requeueable deps ti=<TaskInstance: raddit_data_pipeline.popularity_data_injection manual__2023-10-09T21:11:04.419599+00:00 [queued]>
[2023-10-09T21:11:38.681+0000] {taskinstance.py:1361} INFO - Starting attempt 1 of 2
[2023-10-09T21:11:38.705+0000] {taskinstance.py:1382} INFO - Executing <Task(PythonOperator): popularity_data_injection> on 2023-10-09 21:11:04.419599+00:00
[2023-10-09T21:11:38.718+0000] {standard_task_runner.py:57} INFO - Started process 211 to run task
[2023-10-09T21:11:38.732+0000] {standard_task_runner.py:84} INFO - Running: ['***', 'tasks', 'run', 'raddit_data_pipeline', 'popularity_data_injection', 'manual__2023-10-09T21:11:04.419599+00:00', '--job-id', '9', '--raw', '--subdir', 'DAGS_FOLDER/raddit.py', '--cfg-path', '/tmp/tmpuuouf97j']
[2023-10-09T21:11:38.741+0000] {standard_task_runner.py:85} INFO - Job 9: Subtask popularity_data_injection
[2023-10-09T21:11:38.838+0000] {task_command.py:415} INFO - Running <TaskInstance: raddit_data_pipeline.popularity_data_injection manual__2023-10-09T21:11:04.419599+00:00 [running]> on host 4e554196f202
[2023-10-09T21:11:38.975+0000] {taskinstance.py:1660} INFO - Exporting env vars: AIRFLOW_CTX_DAG_OWNER='MSc DS-7029-20275335' AIRFLOW_CTX_DAG_ID='raddit_data_pipeline' AIRFLOW_CTX_TASK_ID='popularity_data_injection' AIRFLOW_CTX_EXECUTION_DATE='2023-10-09T21:11:04.419599+00:00' AIRFLOW_CTX_TRY_NUMBER='1' AIRFLOW_CTX_DAG_RUN_ID='manual__2023-10-09T21:11:04.419599+00:00'
[2023-10-09T21:11:39.085+0000] {taskinstance.py:1943} ERROR - Task failed with exception
Traceback (most recent call last):
  File "/home/airflow/.local/lib/python3.8/site-packages/airflow/operators/python.py", line 192, in execute
    return_value = self.execute_callable()
  File "/home/airflow/.local/lib/python3.8/site-packages/airflow/operators/python.py", line 209, in execute_callable
    return self.python_callable(*self.op_args, **self.op_kwargs)
  File "/opt/airflow/dags/raddit.py", line 246, in popularity_data_injection
    insert_popularity_data(df, "popularity_data")
  File "/opt/airflow/plugins/includes/mysql_query_executor.py", line 14, in insert_popularity_data
    mysql_connection = mysql_hook.get_conn()
  File "/home/airflow/.local/lib/python3.8/site-packages/airflow/providers/mysql/hooks/mysql.py", line 180, in get_conn
    conn = self.connection or self.get_connection(getattr(self, self.conn_name_attr))
  File "/home/airflow/.local/lib/python3.8/site-packages/airflow/hooks/base.py", line 72, in get_connection
    conn = Connection.get_connection_from_secrets(conn_id)
  File "/home/airflow/.local/lib/python3.8/site-packages/airflow/models/connection.py", line 477, in get_connection_from_secrets
    raise AirflowNotFoundException(f"The conn_id `{conn_id}` isn't defined")
airflow.exceptions.AirflowNotFoundException: The conn_id `mysql_conn_id` isn't defined
[2023-10-09T21:11:39.103+0000] {taskinstance.py:1400} INFO - Marking task as UP_FOR_RETRY. dag_id=raddit_data_pipeline, task_id=popularity_data_injection, execution_date=20231009T211104, start_date=20231009T211138, end_date=20231009T211139
[2023-10-09T21:11:39.128+0000] {standard_task_runner.py:104} ERROR - Failed to execute job 9 for task popularity_data_injection (The conn_id `mysql_conn_id` isn't defined; 211)
[2023-10-09T21:11:39.185+0000] {local_task_job_runner.py:228} INFO - Task exited with return code 1
[2023-10-09T21:11:39.244+0000] {taskinstance.py:2784} INFO - 0 downstream tasks scheduled from follow-on schedule check
